Workbook

Sheet 결제상세
A1: NO | B1: PG사 | C1: 부문 | D1: 브랜드 | E1: 상점아이디(MID) | F1: 정산액 입금일 | G1: 매출일 | H1: 교재 환불부채 | I1: 결제/취소일 | J1: 주문번호 | K1: 유하다요 구분값 | L1: 결제수단 | M1: 결제상태 | N1: 결제기관 | O1: 구매자명 | P1: 구매자 아이디 | Q1: 결제/환불 | R1: 현물출고일 | S1: 강의미공개 | T1: 교재미출고 | U1: 환급 | V1: 유하다요환급 | W1: 구매상품 | X1: IP콜라보 | Y1: 선수수익_계약부채 | Z1: 결제·취소액 (A)
A2: 1 | B2: 토스 | C2: 퍼블리싱 | D2: 유하다요 | E2: im_yuhadayo | F2: 2026-03-05 | G2: 46081 | I2: 2026-02-28 | J2: imp_073604487135 | K2: =A3&"_"&J3 | L2: 신용·체크카드 | M2: 완료 | N2: 국민카드 | O2: Yunkyung | Q2: 결제 | W2: 2026 NEW 전강좌 올패키지 MAX | Z2: 299900
A3: 2 | B3: 토스 | C3: 퍼블리싱 | D3: 유하다요 | E3: im_yuhadayo | F3: 2026-03-05 | G3: 46081 | I3: 2026-02-28 | J3: imp_833517466576 | K3: =A4&"_"&J4 | L3: 신용·체크카드 | M3: 완료 | N3: 국민카드 | O3: 문영민 | Q3: 결제 | W3: 2026 NEW 전강좌 올패키지 MAX | Z3: 299900
A4: 3 | B4: 토스 | C4: 퍼블리싱 | D4: 유하다요 | E4: im_yuhadayo | F4: 2026-03-05 | G4: 46081 | I4: 2026-02-28 | J4: imp_355302391690 | K4: =A5&"_"&J5 | L4: 신용·체크카드 | M4: 완료 | N4: 현대카드 | O4: 이수진 | Q4: 결제 | W4: 2026 NEW 전강좌 올패키지 MAX | Z4: 455100
A5: 4 | B5: 토스 | C5: 퍼블리싱 | D5: 유하다요 | E5: im_yuhadayo | F5: 2026-03-05 | G5: 46081 | I5: 2026-02-28 | J5: imp_380552097593 | K5: =A6&"_"&J6 | L5: 신용·체크카드 | M5: 완료 | N5: 국민카드 | O5: 이대웅 | Q5: 결제 | W5: 2026 NEW 전강좌 올패키지 MAX | Z5: 455100
A6: 5 | B6: 토스 | C6: 퍼블리싱 | D6: 유하다요 | E6: im_yuhadayo | F6: 2026-03-05 | G6: 46081 | I6: 2026-02-28 | J6: imp_384831894097 | K6: =A7&"_"&J7 | L6: 가상계좌 | M6: 완료 | N6: 부산 | O6: 오수현 | Q6: 결제 | W6: 2026 JLPT 합격패키지 | Z6: 269000
A7: 6 | B7: 토스 | C7: 퍼블리싱 | D7: 유하다요 | E7: im_yuhadayo | F7: 2026-03-05 | G7: 46081 | I7: 2026-02-28 | J7: imp_917309141624 | K7: =A8&"_"&J8 | L7: 신용·체크카드 | M7: 완료 | N7: 롯데카드 | O7: 전오영 | Q7: 결제 | W7: 2026 NEW 전강좌 올패키지 MAX | Z7: 249900
A8: 7 | B8: 토스 | C8: 퍼블리싱 | D8: 유하다요 | E8: im_yuhadayo | F8: 2026-03-05 | G8: 46081 | I8: 2026-02-28 | J8: imp_368210886377 | K8: =A9&"_"&J9 | L8: 신용·체크카드 | M8: 완료 | N8: 신한카드 | O8: 정다운 | Q8: 결제 | W8: 2026 NEW 전강좌 올패키지 MAX | Z8: 249900
A9: 8 | B9: 토스 | C9: 퍼블리싱 | D9: 유하다요 | E9: im_yuhadayo | F9: 2026-03-05 | G9: 46081 | I9: 2026-02-28 | J9: imp_968884602264 | K9: =A10&"_"&J10 | L9: 신용·체크카드 | M9: 완료 | N9: 국민카드 | O9: 이영란 | Q9: 결제 | W9: 2026 NEW 전강좌 올패키지 MAX | Z9: 455100
A10: 9 | B10: 토스 | C10: 퍼블리싱 | D10: 유하다요 | E10: im_yuhadayo | F10: 2026-03-05 | G10: 46081 | I10: 2026-02-28 | J10: imp_262783396153 | K10: =A11&"_"&J11 | L10: 신용·체크카드 | M10: 완료 | N10: 삼성카드 | O10: 정희정 | Q10: 결제 | W10: 2026 NEW 전강좌 올패키지 MAX | Z10: 299900
A11: 10 | B11: 토스 | C11: 퍼블리싱 | D11: 유하다요 | E11: im_yuhadayo | F11: 2026-03-05 | G11: 46081 | I11: 2026-02-28 | J11: imp_094081140288 | K11: =A12&"_"&J12 | L11: 신용·체크카드 | M11: 완료 | N11: 현대카드 | O11: 이예헌 | Q11: 결제 | W11: 2026 NEW 전강좌 올패키지 MAX | Z11: 369900
A12: 11 | B12: 토스 | C12: 퍼블리싱 | D12: 유하다요 | E12: im_yuhadayo | F12: 2026-03-05 | G12: 46081 | I12: 2026-02-28 | J12: imp_152844333283 | K12: =A13&"_"&J13 | L12: 신용·체크카드 | M12: 완료 | N12: 신한카드 | O12: 홍동희 | Q12: 결제 | W12: 2026 NEW 전강좌 올패키지 MAX | Z12: 369900
A13: 12 | B13: 토스 | C13: 퍼블리싱 | D13: 유하다요 | E13: im_yuhadayo | F13: 2026-03-05 | G13: 46081 | I13: 2026-02-28 | J13: imp_021765592025 | K13: =A14&"_"&J14 | L13: 신용·체크카드 | M13: 완료 | N13: 국민카드 | O13: 오송주 | Q13: 결제 | W13: 2026 NEW 전강좌 올패키지 MAX | Z13: 385100
... A31: 30 | B31: 토스 | C31: 퍼블리싱 | D31: 유하다요 | E31: im_yuhadayo | F31: 2026-03-05 | G31: 46081 | I31: 2026-02-28 | J31: imp_509177637397 | K31: =A32&"_"&J32 | L31: 신용·체크카드 | M31: 완료 | N31: 비씨카드 | O31: 유원우 | Q31: 결제 | W31: 2026 NEW 전강좌 올패키지 MAX | Z31: 299900
A32: 31 | B32: 토스 | C32: 포도 | D32: 포도 | E32: im_respeak | F32: 2026-03-05 | G32: 46081 | I32: 2026-02-28 | J32: PODO_F_908782_20260228T14471 | L32: 신용·체크카드 | M32: 완료 | N32: 신한카드 | O32: 김다희 | Q32: 결제 | W32: 일본어 무제한 12개월 | Z32: 1242000
A33: 32 | B33: 토스 | C33: 포도 | D33: 포도 | E33: im_respeak | F33: 2026-03-05 | G33: 46081 | I33: 2026-02-28 | J33: PODO_F_69802_20260228T14434 | L33: 신용·체크카드 | M33: 완료 | N33: 국민카드 | O33: 박경민 | Q33: 결제 | W33: 일본어 무제한 12개월 | Z33: 1272000
A34: 33 | B34: 토스 | C34: 포도 | D34: 포도 | E34: im_respeak | F34: 2026-03-05 | G34: 46081 | I34: 2026-02-28 | J34: PODO_F_907877_20260228T14153 | L34: 신용·체크카드 | M34: 완료 | N34: 해외MASTER | O34: 서유진 | Q34: 결제 | W34: 일본어 무제한 6개월 | Z34: 730200
A35: 34 | B35: 토스 | C35: 포도 | D35: 포도 | E35: im_respeak | F35: 2026-03-05 | G35: 46081 | I35: 2026-02-28 | J35: PODO_F_905489_20260228T13362 | L35: 신용·체크카드 | M35: 완료 | N35: 삼성카드 | O35: 유석현 | Q35: 결제 | W35: 일본어 무제한 12개월 | Z35: 1267000
A36: 35 | B36: 토스 | C36: 포도 | D36: 포도 | E36: im_respeak | F36: 2026-03-05 | G36: 46081 | I36: 2026-02-28 | J36: PODO_F_82679_20260228T12462 | L36: 신용·체크카드 | M36: 완료 | N36: 국민카드 | O36: 김예진 | Q36: 결제 | W36: 일본어 무제한 12개월 | Z36: 1272000
A37: 36 | B37: 토스 | C37: 포도 | D37: 포도 | E37: im_respeak | F37: 2026-03-05 | G37: 46081 | I37: 2026-02-28 | J37: PODO_F_909016_20260228T12351 | L37: 신용·체크카드 | M37: 완료 | N37: 현대카드 | O37: 가초롱 | Q37: 결제 | W37: 영어 무제한 6개월 | Z37: 510600
A38: 37 | B38: 토스 | C38: 포도 | D38: 포도 | E38: im_respeak | F38: 2026-03-05 | G38: 46081 | I38: 2026-02-28 | J38: PODO_F_908985_20260228T12070 | L38: 신용·체크카드 | M38: 완료 | N38: 현대카드 | O38: 소만성 | Q38: 결제 | W38: 일본어 라이트 3개월 | Z38: 319800
A39: 38 | B39: 토스 | C39: 포도 | D39: 포도 | E39: im_respeak | F39: 2026-03-05 | G39: 46081 | I39: 2026-02-28 | J39: PODO_F_908611_20260228T12053 | L39: 신용·체크카드 | M39: 완료 | N39: 농협NH | O39: 최지희 | Q39: 결제 | W39: 영어 무제한 6개월 | Z39: 510600
A40: 39 | B40: 토스 | C40: 포도 | D40: 포도 | E40: im_respeak | F40: 2026-03-05 | G40: 46081 | I40: 2026-02-28 | J40: PODO_F_907056_20260228T11310 | L40: 신용·체크카드 | M40: 완료 | N40: 삼성카드 | O40: 박채은 | Q40: 결제 | W40: 영어 무제한 12개월 | Z40: 948000
A41: 40 | B41: 토스 | C41: 포도 | D41: 포도 | E41: im_respeak | F41: 2026-03-05 | G41: 46081 | I41: 2026-02-28 | J41: PODO_F_874869_20260228T11282 | L41: 신용·체크카드 | M41: 완료 | N41: 국민카드 | O41: 김미래 | Q41: 결제 | W41: 영어 무제한 3개월 | Z41: 210210
A42: 41 | B42: 토스 | C42: 포도 | D42: 포도 | E42: im_respeak | F42: 2026-03-05 | G42: 46081 | I42: 2026-02-28 | J42: PODO_F_54569_20260228T10172 | L42: 신용·체크카드 | M42: 완료 | N42: 롯데카드 | O42: 오하경 | Q42: 결제 | W42: 일본어 라이트 6개월 | Z42: 447720
A43: 42 | B43: 토스 | C43: 포도 | D43: 포도 | E43: im_respeak | F43: 2026-03-05 | G43: 46081 | I43: 2026-02-28 | J43: PODO_F_908392_20260228T09582 | L43: 신용·체크카드 | M43: 취소 | N43: 신한카드 | O43: 이은영 | Q43: 환불 | W43: 일본어 프리미엄 12개월 | Z43: -1567000
... A67: 66 | B67: 토스 | C67: 콘텐츠 | D67: 콘텐츠 | E67: im_mylight | F67: 2026-03-05 | G67: 46081 | I67: 2026-02-28 | J67: imp_282860967677 | L67: 신용·체크카드 | M67: 완료 | N67: 현대카드 | O67: 윤희(Lucy) | Q67: 결제 | W67: 더빙 성우 데뷔 학습지 (평생 / 실물) | Z67: 590600
A68: 67 | B68: 토스 | C68: 콘텐츠 | D68: 콘텐츠 | E68: im_mylight | F68: 2026-03-05 | G68: 46081 | I68: 2026-02-28 | J68: imp_659871820609 | L68: 신용·체크카드 | M68: 완료 | N68: 농협NH | O68: 김민희 | Q68: 결제 | S68: =VLOOKUP(J69,얼리버드!$A$2:$B$243,2,0) | W68: 2차 얼리버드)[올인원 패키지] 숏폼부터 브이로그까지, 복붙하면 완성되는 영상 치트키 | Z68: 259000
A69: 68 | B69: 토스 | C69: 콘텐츠 | D69: 콘텐츠 | E69: im_mylight | F69: 2026-03-05 | G69: 46081 | I69: 2026-02-28 | J69: imp_028429849753 | L69: 신용·체크카드 | M69: 완료 | N69: 국민카드 | O69: GRACE | Q69: 결제 | W69: 2차 얼리버드)100만 조회수 터지는 AI 수익화 | Z69: 189000
A70: 69 | B70: 토스 | C70: 콘텐츠 | D70: 콘텐츠 | E70: im_mylight | F70: 2026-03-05 | G70: 46081 | I70: 2026-02-28 | J70: imp_428275984112 | L70: 신용·체크카드 | M70: 완료 | N70: 삼성카드 | O70: 변선영 | Q70: 결제 | W70: [실전] 수키도키의 문구 작가 데뷔 프로젝트 | Z70: 299000
A71: 70 | B71: 토스 | C71: 콘텐츠 | D71: 콘텐츠 | E71: im_mylight | F71: 2026-03-05 | G71: 46081 | I71: 2026-02-28 | J71: imp_865021684327 | L71: 신용·체크카드 | M71: 완료 | N71: 신한카드 | O71: 최미나 | Q71: 결제 | W71: [올인원 패키지] 나의 하루를 담은 시쓰기 | Z71: 269000
A72: 71 | B72: 토스 | C72: 콘텐츠 | D72: 콘텐츠 | E72: im_mylight | F72: 2026-03-05 | G72: 46081 | I72: 2026-02-28 | J72: imp_679725060681 | L72: 신용·체크카드 | M72: 완료 | N72: 삼성카드 | O72: 최원 | Q72: 결제 | R72: =VLOOKUP(J73,현물출고!$A$2:$C$100,3,0) | W72: [데뷔 패키지] 방구석 DJ 패키지 | Z72: 399000
A73: 72 | B73: 토스 | C73: 콘텐츠 | D73: 콘텐츠 | E73: im_mylight | F73: 2026-03-05 | G73: 46081 | I73: 2026-02-28 | J73: imp_733522077343 | L73: 신용·체크카드 | M73: 완료 | N73: 하나카드 | O73: 연승민 | Q73: 결제 | W73: [베이직 패키지] 나의 하루를 담은 시쓰기 | Z73: 179000
A74: 73 | B74: 토스 | C74: 콘텐츠 | D74: 콘텐츠 | E74: im_mylight | F74: 2026-03-05 | G74: 46081 | I74: 2026-02-28 | J74: imp_788971061451 | L74: 신용·체크카드 | M74: 완료 | N74: 농협NH | O74: ANNIE&#128075; | Q74: 결제 | W74: [재테크 입문 패키지] 부자마녀의 재테크 학습지 | Z74: 109000
A75: 74 | B75: 토스 | C75: 마이라이트 | D75: 자체브랜드 | E75: im_mylight | F75: 2026-03-05 | G75: 46081 | I75: 2026-02-28 | J75: imp_877984585131 | L75: 신용·체크카드 | M75: 완료 | N75: 현대카드 | O75: 조남희 | Q75: 결제 | W75: 귀멸의 칼날 콜라보 일본어 패키지 | Z75: 415000
A76: 75 | B76: 토스 | C76: 마이라이트 | D76: 자체브랜드 | E76: im_mylight | F76: 2026-03-05 | G76: 46081 | I76: 2026-02-28 | J76: imp_017526360716 | L76: 신용·체크카드 | M76: 완료 | N76: 현대카드 | O76: . | Q76: 결제 | W76: 이세영의 성형 일본어 Zero 디지털 학습지 | Z76: 144000
A77: 76 | B77: 토스 | C77: 마이라이트 | D77: 자체브랜드 | E77: im_mylight | F77: 2026-03-05 | G77: 46081 | I77: 2026-02-28 | J77: imp_053177799233 | L77: 신용·체크카드 | M77: 완료 | N77: 롯데카드 | O77: 김지유 | Q77: 결제 | W77: 가벼운 영어 베이직 패키지 | Z77: 250000
A78: 77 | B78: 토스 | C78: 마이라이트 | D78: 자체브랜드 | E78: im_mylight | F78: 2026-03-05 | G78: 46081 | I78: 2026-02-28 | J78: imp_480220778978 | L78: 신용·체크카드 | M78: 완료 | N78: 롯데카드 | O78: 홍지우 | Q78: 결제 | W78: 독일어 슈퍼팩 (평생수강, 회화팩 포함) | Z78: 326500
A79: 78 | B79: 토스 | C79: 콘텐츠 | D79: 콘텐츠 | E79: im_mylight | F79: 2026-03-05 | G79: 46081 | I79: 2026-02-28 | J79: imp_040028176339 | L79: 신용·체크카드 | M79: 완료 | N79: 우리카드 | O79: 해인&#10084; | Q79: 결제 | W79: 흥버튼의 스피치 학습지: 평생소장 패키지 | Z79: 184590
A80: 79 | B80: 토스 | C80: 콘텐츠 | D80: 콘텐츠 | E80: im_mylight | F80: 2026-03-05 | G80: 46081 | I80: 2026-02-28 | J80: imp_591023109248 | L80: 신용·체크카드 | M80: 완료 | N80: 국민카드 | O80: 이영준 | Q80: 결제 | R80: 2월출고 | W80: [행운선물 패키지] 김경필의 재테크 로드맵 학습지 | Z80: 251100
...

Sheet MCP_TABLE_20260606_0000
A1: MCP Formula Table | C1: Generated by Spreadsheet formula-table builder
A2: 브랜드 | B2: 신용·체크카드 | C2: 가상계좌
A3: 유하다요 | B3: =IFERROR(SUMIFS('결제상세'!$Z$2:$Z$120,'결제상세'!$D$2:$D$120,$A3,'결제상세'!$L$2:$L$120,B$2),0) | C3: =IFERROR(SUMIFS('결제상세'!$Z$2:$Z$120,'결제상세'!$D$2:$D$120,$A3,'결제상세'!$L$2:$L$120,C$2),0)
A4: 포도 | B4: =IFERROR(SUMIFS('결제상세'!$Z$2:$Z$120,'결제상세'!$D$2:$D$120,$A4,'결제상세'!$L$2:$L$120,B$2),0) | C4: =IFERROR(SUMIFS('결제상세'!$Z$2:$Z$120,'결제상세'!$D$2:$D$120,$A4,'결제상세'!$L$2:$L$120,C$2),0)
A5: 뉴스프레소 | B5: =IFERROR(SUMIFS('결제상세'!$Z$2:$Z$120,'결제상세'!$D$2:$D$120,$A5,'결제상세'!$L$2:$L$120,B$2),0) | C5: =IFERROR(SUMIFS('결제상세'!$Z$2:$Z$120,'결제상세'!$D$2:$D$120,$A5,'결제상세'!$L$2:$L$120,C$2),0)
A6: 콘텐츠 | B6: =IFERROR(SUMIFS('결제상세'!$Z$2:$Z$120,'결제상세'!$D$2:$D$120,$A6,'결제상세'!$L$2:$L$120,B$2),0) | C6: =IFERROR(SUMIFS('결제상세'!$Z$2:$Z$120,'결제상세'!$D$2:$D$120,$A6,'결제상세'!$L$2:$L$120,C$2),0)
A7: 자체브랜드 | B7: =IFERROR(SUMIFS('결제상세'!$Z$2:$Z$120,'결제상세'!$D$2:$D$120,$A7,'결제상세'!$L$2:$L$120,B$2),0) | C7: =IFERROR(SUMIFS('결제상세'!$Z$2:$Z$120,'결제상세'!$D$2:$D$120,$A7,'결제상세'!$L$2:$L$120,C$2),0)
